Workbook

Sheet T. S2 microarray results
A1: Public ID | B1: Gene | I1: Gene description | J1: sch9/wt | K1: ras2/wt | L1: tor1/wt
A2: YAL001C | B2: TFC3 | I2: Largest of six subunits of the RNA polymerase III transcription initiation factor complex (TFIIIC), part of the TauB domain of TFIIIC that binds DNA at the BoxB promoter sites of tRNA and similar genes, cooperates with Tfc6p in DNA binding | J2: -0.3306111 | K2: -0.591746 | L2: -0.4050345
A3: YAL002W | B3: VPS8 | I3: Membrane-associated hydrophilic protein that interacts with the small GTPase, Vps21p, to facilitate soluble vacuolar protein localization, required for localization and trafficking of the CPY sorting receptor, contains a RING finger motif | J3: 0.04337617 | K3: -0.1137375 | L3: 0.006602213
A4: YAL003W | B4: EFB1 | I4: Translation elongation factor 1 beta, stimulates nucleotide exchange to regenerate EF-1 alpha-GTP for the next elongation cycle, part of the EF-1 complex, which facilitates binding of aminoacyl-tRNA to the ribosomal A site | J4: 0.4574232 | K4: 0.3051455 | L4: 0.4256898
A5: YAL005C | B5: SSA2 | C5: SSA1 | I5: ATP binding protein involved in protein folding and vacuolar import of proteins, member of heat shock protein 70 (HSP70) family, associated with the chaperonin-containing T-complex, present in the cytoplasm, vacuolar membrane and cell wall ATPase involved in protein folding and nuclear localization signal (NLS)-directed nuclear transport, member of heat shock protein 70 (HSP70) family, forms a chaperone complex with Ydj1p, localized to the nucleus, cytoplasm, and cell wall | J5: 0.4046161 | K5: 0.5262972 | L5: 0.5405332
A6: YAL007C | B6: ERP2 | I6: Protein that forms a heterotrimeric complex with Erp1p, Emp24p, and Erv25p, member, along with Emp24p and Erv25p, of the p24 family involved in ER to Golgi transport and localized to COPII-coated vesicles | J6: 0.261135 | K6: 0.6099756 | L6: 0.4683093
A7: YAL008W | B7: FUN14 | I7: Mitochondrial protein of unknown function | J7: 0.2856357 | K7: 0.7606662 | L7: 0.4454354
A8: YAL009W | B8: SPO7 | I8: Integral nuclearER membrane protein of unknown function, required for normal nuclear envelope morphology and sporulation | J8: 0.2816513 | K8: 0.3294875 | L8: 0.3487153
A9: YAL010C | B9: MDM10 | I9: Subunit of the mitochondrial sorting and assembly machinery (SAM complex), has a role in assembly of the TOM complex, which mediates protein import through the outer membrane, required for normal mitochondrial morphology and inheritance | J9: -0.1904569 | K9: -0.1016729 | L9: -0.000173538
A10: YAL011W | B10: SWC3 | I10: Protein of unknown function, component of the Swr1p complex that incorporates Htz1p into chromatin, required for formation of nuclear-associated array of smooth endoplasmic reticulum known as karmellae | J10: -0.2772261 | K10: -0.5650292 | L10: -0.4100454
A11: YAL012W | B11: CYS3 | I11: Cystathionine gamma-lyase, catalyzes one of the two reactions involved in the transsulfuration pathway that yields cysteine from homocysteine with the intermediary formation of cystathionine, | J11: 0.3629012 | K11: 2.289331 | L11: 1.463729
A12: YAL013W | B12: DEP1 | I12: Transcriptional modulator involved in the regulation of structural genes involved in phospholipid biosynthesis, also participates in regulation of metabolically unrelated genes as well as maintenance of mating efficiency and sporulation | J12: 0.2752761 | K12: 0.004748148 | L12: 0.2537479
A13: YAL014C | B13: SYN8 | I13: Endosomal SNARE related to mammalian syntaxin 8 | J13: 0.4895598 | K13: 0.6373698 | L13: 0.4405245
A14: YAL015C | B14: NTG1 | I14: DNA N-glycosylase and apurinicapyrimidinic (AP) lyase involved in base excision repair, localizes to the nucleus and mitochondrion | J14: 0.3314654 | K14: -0.3319789 | L14: 0.05383845
A15: YAL016C-B | B15: --- | I15: Identified by fungal homology and RT-PCR | J15: -0.2296202 | K15: -0.25955 | L15: -0.1683807
A16: YAL016W | B16: TPD3 | I16: Regulatory subunit A of the heterotrimeric protein phosphatase 2A, which also contains regulatory subunit Cdc55p and either catalytic subunit Pph21p or Pph22p, required for cell morphogenesis and for transcription by RNA polymerase III | J16: -0.1345241 | K16: -0.1092769 | L16: -0.006014937
A17: YAL017W | B17: PSK1 | I17: One of two (see also PSK2) PAS domain containing ST protein kinases, coordinately regulates protein synthesis and carbohydrate metabolism and storage in response to a unknown metabolite that reflects nutritional status | J17: -0.3032663 | K17: -0.729649 | L17: -0.4077454
... A61: YAL062W | B61: GDH3 | I61: NADP(+)-dependent glutamate dehydrogenase, synthesizes glutamate from ammonia and alpha-ketoglutarate, rate of alpha-ketoglutarate utilization differs from Gdh1p, expression regulated by nitrogen and carbon sources | J61: 0.1478735 | K61: 0.3257182 | L61: -0.02448432
A62: YAL063C | B62: FLO5 | C62: FLO9 | D62: FLO1 | I62: Lectin-like protein involved in flocculation, cell wall protein that binds to mannose chains on the surface of other cells, confers floc-forming ability that is chymotrypsin resistant but heat labile, similar to Flo1p Lectin-like protein with similarity to Flo1p, thought to be expressed and involved in flocculation Lectin-like protein involved in flocculation, cell wall protein that binds to mannose chains on the surface of other cells, confers floc-forming ability that is chymotrypsin sensitive and heat resistant, similar to Flo5p | J62: -0.08677335 | K62: 0.474296 | L62: 0.1042248
A63: YAL063C-A | B63: --- | I63: Identified by expression profiling and mass spectrometry | J63: -0.2138284 | K63: 1.052111 | L63: 0.3248847
A64: YAL064C-A | B64: --- | I64: Hypothetical protein | J64: -0.1279343 | K64: 0.09968682 | L64: -0.03509193
A65: YAL064W | B65: --- | I65: Hypothetical protein | J65: -0.1943685 | K65: -0.1566463 | L65: -0.150287
A66: YAL064W-B | B66: --- | I66: Hypothetical protein | J66: -0.4461807 | K66: -0.1629928 | L66: -0.4600532
A67: YAL065C | B67: --- | I67: Hypothetical protein | J67: -0.6079561 | K67: -0.4641998 | L67: -0.4185536
A68: YAL067C | B68: SEO1 | I68: Putative permease, member of the allantoate transporter subfamily of the major facilitator superfamily, mutation confers resistance to ethionine sulfoxide | J68: -0.2041933 | K68: 1.521019 | L68: 0.5804801
A69: YAL067W-A | B69: --- | I69: Identified by gene-trapping, microarray-based expression analysis, and genome-wide homology searching Hypothetical protein Hypothetical protein Identified by gene-trapping, microarray-based expression analysis, and genome-wide homology searching | J69: 0.03219915 | K69: 0.4661268 | L69: 0.1737204
A70: YAL068C | B70: PAU4 | C70: PAU6 | D70: PAU1 | E70: PAU2 | F70: DAN3 | I70: Part of 23-member seripauperin multigene family encoded mainly in subtelomeric regions, active during alcoholic fermentation, regulated by anaerobiosis, negatively regulated by oxygen, repressed by heme Hypothetical protein Part of 23-member seripauperin multigene family encoded mainly in subtelomeric regions, active during alcoholic fermentation, regulated by anaerobiosis, negatively regulated by oxygen, repressed by heme Hypothetical protein Part of 23-member seripauperin multigene family encoded mainly in subtelomeric regions, active during alcoholic fermentation, regulated by anaerobiosis, negatively regulated by oxygen, repressed by heme Hypothetical protein Hypothetical protein Hypothetical protein Hypothetical protein Part of 23-member seripauperin multigene family encoded mainly in subtelomeric regions, active during alcoholic fermentation, regulated by anaerobiosis, negatively regulated by oxygen, repressed by heme Hypothetical protein Cell wall mannoprotein with similarity to Tir1p, Tir2p, Tir3p, and Tir4p, expressed under anaerobic conditions, completely repressed during aerobic growth Hypothetical protein Hypothetical protein identified by homology. See FEBS Letters [2000] 487:31-36. | J70: -0.3969555 | K70: 0.2500766 | L70: 0.3103923
A71: YAR002C-A | B71: ERP1 | I71: Protein that forms a heterotrimeric complex with Erp2p, Emp24p, and Erv25p, member, along with Emp24p and Erv25p, of the p24 family involved in ER to Golgi transport and localized to COPII-coated vesicles | J71: -0.004772137 | K71: 0.3688506 | L71: 0.199006
A72: YAR002W | B72: NUP60 | I72: Subunit of the nuclear pore complex (NPC), functions to anchor Nup2p to the NPC in a dynamic process that is controlled by the nucleoplasmic concentration of Gsp1p-GTP, potential Cdc28p substrate | J72: -0.2923209 | K72: -0.0904122 | L72: -0.1713251
A73: YAR003W | B73: SWD1 | I73: Subunit of the COMPASS (Set1C) complex, which methylates Rad6p ubiquitinated histone H3 on lysine 4 and is required in transcriptional silencing near telomeres, WD40 beta propeller superfamily member with similarity to mammalian Rbbp7 | J73: -0.07463264 | K73: -0.005272889 | L73: -0.147948
A74: YAR007C | B74: RFA1 | I74: Subunit of heterotrimeric Replication Factor A (RF-A), which is a highly conserved single-stranded DNA binding protein involved in DNA replication, repair, and recombination | J74: -0.6220847 | K74: -0.8557639 | L74: -0.555766
A75: YAR008W | B75: SEN34 | I75: Subunit of the tRNA splicing endonuclease, which is composed of Sen2p, Sen15p, Sen34p, and Sen54p, Sen34p contains the active site for tRNA 3 splice site cleavage and has similarity to Sen2p and to Archaeal tRNA splicing endonuclease | J75: 0.01630292 | K75: -0.501172 | L75: 0.3310486
A76: YAR009C | B76: --- | I76: TyB Gag-Pol protein, proteolytically processed to make the Gag, RT, PR, and IN proteins that are required for retrotransposition TyB Gag-Pol protein, proteolytically processed to make the Gag, RT, PR, and IN proteins that are required for retrotransposition TyB Gag-Pol protein, proteolytically processed to make the Gag, RT, PR, and IN proteins that are required for retrotransposition TyB Gag-Pol protein, proteolytically processed to make the Gag, RT, PR, and IN proteins that are required for retrotransposition TyB Gag-Pol protein, proteolytically processed to make the Gag, RT, PR, and IN proteins that are required for retrotransposition TyB Gag-Pol protein, proteolytically processed to make the Gag, RT, PR, and IN proteins that are required for retrotransposition TyB Gag-Pol protein, proteolytically processed to make the Gag, RT, PR, and IN proteins that are required for retrotransposition TyB Gag-Pol protein, proteolytically processed to make the Gag, RT, PR, and IN proteins that are required for retrotransposition TyB Gag-Pol protein, proteolytically processed to make the Gag, RT, PR, and IN proteins that are required for retrotransposition TyB Gag-Pol protein, proteolytically processed to make the Gag, RT, PR, and IN proteins that are required for retrotransposition TyB Gag-Pol protein, proteolytically processed to make the Gag, RT, PR, and IN proteins that are required for retrotransposition TyB Gag-Pol protein, proteolytically processed to make the Gag, RT, PR, and IN proteins that are required for retrotransposition TyB Gag-Pol protein, proteolytically processed to make the Gag, RT, PR, and IN proteins that are required for retrotransposition TyB Gag-Pol protein, proteolytically processed to make the Gag, RT, PR, and IN proteins that are required for retrotransposition TyB Gag-Pol protein, proteolytically processed to make the Gag, RT, PR, and IN proteins that are required for retrotransposition TyB Gag-Pol protein, proteolytically processed to make the Gag, RT, PR, and IN proteins that are required for retrotransposition TyB Gag-Pol protein, proteolytically processed to make the Gag, RT, PR, and IN proteins that are required for retrotransposition Ty ORF TyB Gag-Pol protein, proteolytically processed to make the Gag, RT, PR, and IN proteins that are required for retrotransposition TyB Gag-Pol protein, proteolytically processed to make the Gag, RT, PR, and IN proteins that are required for retrotransposition TyB Gag-Pol protein, proteolytically processed to make the Gag, RT, PR, and IN proteins that are required for retrotransposition TyB Gag-Pol protein, proteolytically processed to make the Gag, RT, PR, and IN proteins that are required for retrotransposition TyB Gag-Pol protein, proteolytically processed to make the Gag, RT, PR, and IN proteins that are required for retrotransposition TyB Gag-Pol protein, proteolytically processed to make the Gag, RT, PR, and IN proteins that are required for retrotransposition TyB Gag-Pol protein, proteolytically processed to make the Gag, RT, PR, and IN proteins that are required for retrotransposition TyB Gag-Pol protein, proteolytically processed to make the Gag, RT, PR, and IN proteins that are required for retrotransposition TyB Gag-Pol protein, proteolytically processed to make the Gag, RT, PR, and IN proteins that are required for retrotransposition TyB Gag-Pol protein, proteolytically processed to make the Gag, RT, PR, and IN proteins that are required for retrotransposition TyB Gag-Pol protein, proteolytically processed to make the Gag, RT, PR, and IN proteins that are required for retrotransposition TyB Gag-Pol protein, proteolytically processed to make the Gag, RT, PR, and IN proteins that are required for retrotransposition TyB Gag-Pol protein, proteolytically processed to make the Gag, RT, PR, and IN proteins that are required for retrotransposition TyB Gag-Pol protein, proteolytically processed to make the Gag, RT, PR, and IN proteins that are required for retrotransposition TyB Gag-Pol protein, proteolytically processed to make the Gag, RT, PR, and IN proteins that are required for retrotransposition TyB Gag-Pol protein, proteolytically processed to make the Gag, RT, PR, and IN proteins that are required for retrotransposition TyB Gag-Pol protein, proteolytically processed to make the Gag, RT, PR, and IN proteins that are required for retrotransposition TyB Gag-Pol protein, proteolytically processed to make the Gag, RT, PR, and IN proteins that are required for retrotransposition TyB Gag-Pol protein, proteolytically processed to make the Gag, RT, PR, and IN proteins that are required for retrotransposition TyB Gag-Pol protein, proteolytically processed to make the Gag, RT, PR, and IN proteins that are required for retrotransposition TyB Gag-Pol protein, proteolytically processed to make the Gag, RT, PR, and IN proteins that are required for retrotransposition TyB Gag-Pol protein, proteolytically processed to make the Gag, RT, PR, and IN proteins that are required for retrotransposition TyB Gag-Pol protein, proteolytically processed to make the Gag, RT, PR, and IN proteins that are required for retrotransposition | J76: -1.370308 | K76: -0.9859324 | L76: -0.6930766
A77: YAR010C | B77: --- | I77: TyB Gag-Pol protein, proteolytically processed to make the Gag, RT, PR, and IN proteins that are required for retrotransposition TyA Gag protein, the main structural constituent of virus-like particles (VLPs) TyB Gag-Pol protein, proteolytically processed to make the Gag, RT, PR, and IN proteins that are required for retrotransposition TyA Gag protein, the main structural constituent of virus-like particles (VLPs) TyA Gag protein, the main structural constituent of virus-like particles (VLPs) TyB Gag-Pol protein, proteolytically processed to make the Gag, RT, PR, and IN proteins that are required for retrotransposition TyB Gag-Pol protein, proteolytically processed to make the Gag, RT, PR, and IN proteins that are required for retrotransposition TyA Gag protein, the main structural constituent of virus-like particles (VLPs) TyB Gag-Pol protein, proteolytically processed to make the Gag, RT, PR, and IN proteins that are required for retrotransposition TyA Gag protein, the main structural constituent of virus-like particles (VLPs) TyB Gag-Pol protein, proteolytically processed to make the Gag, RT, PR, and IN proteins that are required for retrotransposition TyA Gag protein, the main structural constituent of virus-like particles (VLPs) TyB Gag-Pol protein, proteolytically processed to make the Gag, RT, PR, and IN proteins that are required for retrotransposition TyA Gag protein, the main structural constituent of virus-like particles (VLPs) TyB Gag-Pol protein, proteolytically processed to make the Gag, RT, PR, and IN proteins that are required for retrotransposition TyB Gag-Pol protein, proteolytically processed to make the Gag, RT, PR, and IN proteins that are required for retrotransposition TyA Gag protein, the main structural constituent of virus-like particles (VLPs) TyB Gag-Pol protein, proteolytically processed to make the Gag, RT, PR, and IN proteins that are required for retrotransposition TyA Gag protein, the main structural constituent of virus-like particles (VLPs) Identified by expression profiling and mass spectrometry TyB Gag-Pol protein, proteolytically processed to make the Gag, RT, PR, and IN proteins that are required for retrotransposition TyA Gag protein, the main structural constituent of virus-like particles (VLPs) TyA Gag protein, the main structural constituent of virus-like particles (VLPs) TyB Gag-Pol protein, proteolytically processed to make the Gag, RT, PR, and IN proteins that are required for retrotransposition TyA Gag protein, the main structural constituent of virus-like particles (VLPs) TyA Gag protein, the main structural constituent of virus-like particles (VLPs) TyB Gag-Pol protein, proteolytically processed to make the Gag, RT, PR, and IN proteins that are required for retrotransposition TyA Gag protein, the main structural constituent of virus-like particles (VLPs) TyB Gag-Pol protein, proteolytically processed to make the Gag, RT, PR, and IN proteins that are required for retrotransposition Ty ORF TyB Gag-Pol protein, proteolytically processed to make the Gag, RT, PR, and IN proteins that are required for retrotransposition TyB Gag-Pol protein, proteolytically processed to make the Gag, RT, PR, and IN proteins that are required for retrotransposition TyA Gag protein, the main structural constituent of virus-like particles (VLPs) TyB Gag-Pol protein, proteolytically processed to make the Gag, RT, PR, and IN proteins that are required for retrotransposition TyA Gag protein, the main structural constituent of virus-like particles (VLPs) TyA Gag protein, the main structural constituent of virus-like particles (VLPs) TyB Gag-Pol protein, proteolytically processed to make the Gag, RT, PR, and IN proteins that are required for retrotransposition TyA Gag protein, the main structural constituent of virus-like particles (VLPs) TyB Gag-Pol protein, proteolytically processed to make the Gag, RT, PR, and IN proteins that are required for retrotransposition TyA Gag protein, the main structural constituent of virus-like particles (VLPs) TyB Gag-Pol protein, proteolytically processed to make the Gag, RT, PR, and IN proteins that are required for retrotransposition TyB Gag-Pol protein, proteolytically processed to make the Gag, RT, PR, and IN proteins that are required for retrotransposition TyA Gag protein, the main structural constituent of virus-like particles (VLPs) TyA Gag protein, the main structural constituent of virus-like particles (VLPs) TyB Gag-Pol protein, proteolytically processed to make the Gag, RT, PR, and IN proteins that are required for retrotransposition TyA Gag protein, the main structural constituent of virus-like particles (VLPs) TyB Gag-Pol protein, proteolytically processed to make the Gag, RT, PR, and IN proteins that are required for retrotransposition TyA Gag protein, the main structural constituent of virus-like particles (VLPs) TyB Gag-Pol protein, proteolytically processed to make the Gag, RT, PR, and IN proteins that are required for retrotransposition TyB Gag-Pol protein, proteolytically processed to make the Gag, RT, PR, and IN proteins that are required for retrotransposition TyA Gag protein, the main structural constituent of virus-like particles (VLPs) TyB Gag-Pol protein, proteolytically processed to make the Gag, RT, PR, and IN proteins that are required for retrotransposition TyA Gag protein, the main structural constituent of virus-like particles (VLPs) TyB Gag-Pol protein, proteolytically processed to make the Gag, RT, PR, and IN proteins that are required for retrotransposition TyA Gag protein, the main structural constituent of virus-like particles (VLPs) TyA Gag protein, the main structural constituent of virus-like particles (VLPs) TyB Gag-Pol protein, proteolytically processed to make the Gag, RT, PR, and IN proteins that are required for retrotransposition TyA Gag protein, the main structural constituent of virus-like particles (VLPs) TyB Gag-Pol protein, proteolytically processed to make the Gag, RT, PR, and IN proteins that are required for retrotransposition | J77: -0.5123691 | K77: -0.6682571 | L77: -0.5717717
A78: YAR014C | B78: BUD14 | I78: Protein involved in bud-site selection, diploid mutants display a random budding pattern instead of the wild-type bipolar pattern | J78: -0.507132 | K78: -0.9840414 | L78: -0.4319503
A79: YAR015W | B79: ADE1 | I79: N-succinyl-5-aminoimidazole-4-carboxamide ribotide (SAICAR) synthetase, required for de novo purine nucleotide biosynthesis, red pigment accumulates in mutant cells deprived of adenine | J79: 0.2633153 | K79: -0.115271 | L79: 0.7528612
A80: YAR018C | B80: KIN3 | I80: Nonessential protein kinase with unknown cellular role | J80: -0.2154747 | K80: -0.07369933 | L80: 0.1284762
A81: YAR019C | B81: CDC15 | I81: Protein kinase of the Mitotic Exit Network that is localized to the spindle pole bodies at late anaphase, promotes mitotic exit by directly switching on the kinase activity of Dbf2p | J81: -0.01695682 | K81: 0.1482022 | L81: -0.06900086
A82: YAR020C | B82: PAU7 | I82: Part of 23-member seripauperin multigene family, active during alcoholic fermentation, regulated by anaerobiosis, inhibited by oxygen, repressed by heme | J82: -0.03812366 | K82: 0.4380359 | L82: 0.2873593
... A87: YAR031W | B87: PRM9 | I87: Pheromone-regulated protein with 3 predicted transmembrane segments and an FF sequence, a motif involved in COPII binding | J87: 0.05818872 | K87: -0.0438543 | L87: 0.03389733
...

Sheet Count
A1: Gene1 | B1: Gene2 | C1: Gene3 | D1: Gene4 | E1: Gene5 | F1: Gene6 | G1: Gene7 | M1: COUNT :
A2: TFC3 | M2: A | N2: B | O2: C | P2: D | Q2: E | R2: F | S2: G | T2: H
A3: VPS8 | M3: =COUNTA(A$2:A$5668) -> 5667 | N3: =COUNTA(B$2:B$5668) -> 131 | O3: =COUNTA(C$2:C$5668) -> 29 | P3: =COUNTA(D$2:D$5668) -> 21 | Q3: =COUNTA(E$2:E$5668) -> 17 | R3: =COUNTA(F$2:F$5668) -> 10 | S3: =COUNTA(G$2:G$5668) -> 5 | T3: =COUNTA(H$2:H$5668) -> 0
A4: EFB1
A5: SSA2 | B5: SSA1
A6: ERP2 | K6: #Cadidate | L6: Genes: | P6: #Known | Q6: Longivity | R6: Genes:
A7: FUN14 | K7: YGL007W | L7: =COUNTIF($A$2:$G$5668,K7) -> 0 | P7: AGP1 | Q7: =COUNTIF($A$2:$G$5668,P7) -> 1
A8: SPO7 | K8: UBP6 | L8: =COUNTIF($A$2:$G$5668,K8) -> 1 | P8: ATP2 | Q8: =COUNTIF($A$2:$G$5668,P8) -> 1
A9: MDM10 | K9: HFI1 | L9: =COUNTIF($A$2:$G$5668,K9) -> 1 | P9: BCY1 | Q9: =COUNTIF($A$2:$G$5668,P9) -> 1
A10: SWC3 | K10: HST4 | L10: =COUNTIF($A$2:$G$5668,K10) -> 1 | P10: BRE5 | Q10: =COUNTIF($A$2:$G$5668,P10) -> 1
A11: CYS3 | K11: AKR1 | L11: =COUNTIF($A$2:$G$5668,K11) -> 1 | P11: CCS1 | Q11: =COUNTIF($A$2:$G$5668,P11) -> 1
A12: DEP1 | K12: ALF1 | L12: =COUNTIF($A$2:$G$5668,K12) -> 1 | P12: CDC25 | Q12: =COUNTIF($A$2:$G$5668,P12) -> 1
A13: SYN8 | K13: VPS30 | L13: =COUNTIF($A$2:$G$5668,K13) -> 1 | P13: CDC6 | Q13: =COUNTIF($A$2:$G$5668,P13) -> 1
A14: NTG1 | K14: SEC22 | L14: =COUNTIF($A$2:$G$5668,K14) -> 1 | P14: CHL1 | Q14: =COUNTIF($A$2:$G$5668,P14) -> 1
A15: --- | K15: PUT3 | L15: =COUNTIF($A$2:$G$5668,K15) -> 1 | P15: CLN3 | Q15: =COUNTIF($A$2:$G$5668,P15) -> 1
A16: TPD3 | K16: SRO9 | L16: =COUNTIF($A$2:$G$5668,K16) -> 1 | P16: CSR2 | Q16: =COUNTIF($A$2:$G$5668,P16) -> 1
A17: PSK1 | K17: GCN3 | L17: =COUNTIF($A$2:$G$5668,K17) -> 1 | P17: CTT1 | Q17: =COUNTIF($A$2:$G$5668,P17) -> 1
A18: --- | K18: HCS1 | L18: =COUNTIF($A$2:$G$5668,K18) -> 1 | P18: CYR1 | Q18: =COUNTIF($A$2:$G$5668,P18) -> 1
... A61: GDH3 | K61: NPT1 | L61: =COUNTIF($A$2:$G$5668,K61) -> 1 | P61: RPD3 | Q61: =COUNTIF($A$2:$G$5668,P61) -> 1
A62: FLO5 | B62: FLO9 | C62: FLO1 | K62: FUN26 | L62: =COUNTIF($A$2:$G$5668,K62) -> 1 | P62: RPL10 | Q62: =COUNTIF($A$2:$G$5668,P62) -> 1
A63: --- | K63: PEX28 | L63: =COUNTIF($A$2:$G$5668,K63) -> 1 | P63: RPL31A | Q63: =COUNTIF($A$2:$G$5668,P63) -> 2
A64: --- | K64: YNL241C | L64: =COUNTIF($A$2:$G$5668,K64) -> 0 | P64: RPL6B | Q64: =COUNTIF($A$2:$G$5668,P64) -> 1
A65: --- | K65: DOA4 | L65: =COUNTIF($A$2:$G$5668,K65) -> 1 | P65: RPO41 | Q65: =COUNTIF($A$2:$G$5668,P65) -> 1
A66: --- | K66: YJL171C | L66: =COUNTIF($A$2:$G$5668,K66) -> 0 | P66: RPS18A | Q66: =COUNTIF($A$2:$G$5668,P66) -> 2
A67: --- | K67: STC2 | L67: =COUNTIF($A$2:$G$5668,K67) -> 0 | P67: RPS18B | Q67: =COUNTIF($A$2:$G$5668,P67) -> 2
A68: SEO1 | K68: AHC1 | L68: =COUNTIF($A$2:$G$5668,K68) -> 1 | P68: RPS6B | Q68: =COUNTIF($A$2:$G$5668,P68) -> 1
A69: --- | K69: YNL266W | L69: =COUNTIF($A$2:$G$5668,K69) -> 0 | P69: RTG3 | Q69: =COUNTIF($A$2:$G$5668,P69) -> 1
A70: PAU4 | B70: PAU6 | C70: PAU1 | D70: PAU2 | E70: DAN3 | K70: RRN10 | L70: =COUNTIF($A$2:$G$5668,K70) -> 1 | P70: SCH9 | Q70: =COUNTIF($A$2:$G$5668,P70) -> 1
A71: ERP1 | K71: DCS1 | L71: =COUNTIF($A$2:$G$5668,K71) -> 1 | P71: SCP1 | Q71: =COUNTIF($A$2:$G$5668,P71) -> 1
A72: NUP60 | K72: ATS1 | L72: =COUNTIF($A$2:$G$5668,K72) -> 1 | P72: SGS1 | Q72: =COUNTIF($A$2:$G$5668,P72) -> 1
A73: SWD1 | K73: RNP1 | L73: =COUNTIF($A$2:$G$5668,K73) -> 1 | P73: SIP2 | Q73: =COUNTIF($A$2:$G$5668,P73) -> 1
A74: RFA1 | K74: GCN2 | L74: =COUNTIF($A$2:$G$5668,K74) -> 1 | P74: sir2 | Q74: =COUNTIF($A$2:$G$5668,P74) -> 1
A75: SEN34 | K75: MCT1 | L75: =COUNTIF($A$2:$G$5668,K75) -> 1 | P75: sir3 | Q75: =COUNTIF($A$2:$G$5668,P75) -> 1
A76: --- | K76: URE2 | L76: =COUNTIF($A$2:$G$5668,K76) -> 1 | P76: sir4 | Q76: =COUNTIF($A$2:$G$5668,P76) -> 1
A77: --- | K77: YET1 | L77: =COUNTIF($A$2:$G$5668,K77) -> 0 | P77: SNF1 | Q77: =COUNTIF($A$2:$G$5668,P77) -> 1
A78: BUD14 | K78: PEX17 | L78: =COUNTIF($A$2:$G$5668,K78) -> 1 | P78: SNF4 | Q78: =COUNTIF($A$2:$G$5668,P78) -> 1
A79: ADE1 | K79: RAD6 | L79: =COUNTIF($A$2:$G$5668,K79) -> 1 | P79: Sod1 | Q79: =COUNTIF($A$2:$G$5668,P79) -> 1
A80: KIN3 | K80: NPR1 | L80: =COUNTIF($A$2:$G$5668,K80) -> 1 | P80: Sod2 | Q80: =COUNTIF($A$2:$G$5668,P80) -> 1
A81: CDC15 | K81: YOR091W | L81: =COUNTIF($A$2:$G$5668,K81) -> 0 | P81: SSD1 | Q81: =COUNTIF($A$2:$G$5668,P81) -> 1
A82: PAU7 | K82: BUD16 | L82: =COUNTIF($A$2:$G$5668,K82) -> 1 | P82: TLC1 | Q82: =COUNTIF($A$2:$G$5668,P82) -> 0
...

Sheet Check
A1: #Candidate Genes | E1: #Known Longivity Genes
A2: {=_xlfn._xlws.FILTER(Count!K7:K127,Count!L7:L127 > 0)} -> UBP6 | E2: {=_xlfn._xlws.FILTER(Count!P7:P92,Count!Q7:Q92 > 0)} -> AGP1
A3: HFI1 | E3: ATP2
A4: HST4 | E4: BCY1
A5: AKR1 | E5: BRE5
A6: ALF1 | E6: CCS1
A7: VPS30 | E7: CDC25
A8: SEC22 | E8: CDC6
A9: PUT3 | E9: CHL1
A10: SRO9 | E10: CLN3
A11: GCN3 | E11: CSR2
A12: HCS1 | E12: CTT1
A13: CDC10 | E13: CYR1
A14: RGD1 | E14: DNA2
... A84: DUR1,2 | E84: ZDS1
A85: ELP2
A86: MLH1
A87: DSE3
A88: RPD3

Sheet CLeaned Data
A1: Public ID | B1: Genes | C1: Types | D1: Name | E1: Known | F1: sch9/wt | G1: ras2/wt | H1: tor1/wt
A2: {=INDEX('T. S2 microarray results'!A:A, MATCH(TRUE, ('T. S2 microarray results'!B:B=B2) + ('T. S2 microarray results'!C:C=B2) + ('T. S2 microarray results'!D:D=B2) + ('T. S2 microarray results'!E:E=B2) + ('T. S2 microarray results'!F:F=B2) + ('T. S2 microarray results'!G:G=B2) + ('T. S2 microarray results'!H:H=B2) > 0, 0))} -> YFR010W | B2: UBP6 | C2: Candidate Gene | D2: =CONCATENATE(IF(C2="Known Longivity Gene","*",""),A2,"/",B2) -> YFR010W/UBP6 | E2: =IF(C2="Known Longivity Gene",1,0) -> 0 | F2: {=INDEX('T. S2 microarray results'!J:J, MATCH(TRUE, ('T. S2 microarray results'!B:B=B2) + ('T. S2 microarray results'!C:C=B2) + ('T. S2 microarray results'!D:D=B2) + ('T. S2 microarray results'!E:E=B2) + ('T. S2 microarray results'!F:F=B2) + ('T. S2 microarray results'!G:G=B2) + ('T. S2 microarray results'!H:H=B2) > 0, 0))} -> 0.1556491 | G2: {=INDEX('T. S2 microarray results'!K:K, MATCH(TRUE, ('T. S2 microarray results'!B:B=B2) + ('T. S2 microarray results'!C:C=B2) + ('T. S2 microarray results'!D:D=B2) + ('T. S2 microarray results'!E:E=B2) + ('T. S2 microarray results'!F:F=B2) + ('T. S2 microarray results'!G:G=B2) + ('T. S2 microarray results'!H:H=B2) > 0, 0))} -> -0.4880185 | H2: {=INDEX('T. S2 microarray results'!L:L, MATCH(TRUE, ('T. S2 microarray results'!B:B=B2) + ('T. S2 microarray results'!C:C=B2) + ('T. S2 microarray results'!D:D=B2) + ('T. S2 microarray results'!E:E=B2) + ('T. S2 microarray results'!F:F=B2) + ('T. S2 microarray results'!G:G=B2) + ('T. S2 microarray results'!H:H=B2) > 0, 0))} -> 0.07698462
A3: {=INDEX('T. S2 microarray results'!A:A, MATCH(TRUE, ('T. S2 microarray results'!B:B=B3) + ('T. S2 microarray results'!C:C=B3) + ('T. S2 microarray results'!D:D=B3) + ('T. S2 microarray results'!E:E=B3) + ('T. S2 microarray results'!F:F=B3) + ('T. S2 microarray results'!G:G=B3) + ('T. S2 microarray results'!H:H=B3) > 0, 0))} -> YPL254W | B3: HFI1 | C3: Candidate Gene | D3: =CONCATENATE(IF(C3="Known Longivity Gene","*",""),A3,"/",B3) -> YPL254W/HFI1 | E3: =IF(C3="Known Longivity Gene",1,0) -> 0 | F3: {=INDEX('T. S2 microarray results'!J:J, MATCH(TRUE, ('T. S2 microarray results'!B:B=B3) + ('T. S2 microarray results'!C:C=B3) + ('T. S2 microarray results'!D:D=B3) + ('T. S2 microarray results'!E:E=B3) + ('T. S2 microarray results'!F:F=B3) + ('T. S2 microarray results'!G:G=B3) + ('T. S2 microarray results'!H:H=B3) > 0, 0))} -> 0.05905491 | G3: {=INDEX('T. S2 microarray results'!K:K, MATCH(TRUE, ('T. S2 microarray results'!B:B=B3) + ('T. S2 microarray results'!C:C=B3) + ('T. S2 microarray results'!D:D=B3) + ('T. S2 microarray results'!E:E=B3) + ('T. S2 microarray results'!F:F=B3) + ('T. S2 microarray results'!G:G=B3) + ('T. S2 microarray results'!H:H=B3) > 0, 0))} -> 0.2101467 | H3: {=INDEX('T. S2 microarray results'!L:L, MATCH(TRUE, ('T. S2 microarray results'!B:B=B3) + ('T. S2 microarray results'!C:C=B3) + ('T. S2 microarray results'!D:D=B3) + ('T. S2 microarray results'!E:E=B3) + ('T. S2 microarray results'!F:F=B3) + ('T. S2 microarray results'!G:G=B3) + ('T. S2 microarray results'!H:H=B3) > 0, 0))} -> -0.1090477
A4: {=INDEX('T. S2 microarray results'!A:A, MATCH(TRUE, ('T. S2 microarray results'!B:B=B4) + ('T. S2 microarray results'!C:C=B4) + ('T. S2 microarray results'!D:D=B4) + ('T. S2 microarray results'!E:E=B4) + ('T. S2 microarray results'!F:F=B4) + ('T. S2 microarray results'!G:G=B4) + ('T. S2 microarray results'!H:H=B4) > 0, 0))} -> YDR191W | B4: HST4 | C4: Candidate Gene | D4: =CONCATENATE(IF(C4="Known Longivity Gene","*",""),A4,"/",B4) -> YDR191W/HST4 | E4: =IF(C4="Known Longivity Gene",1,0) -> 0 | F4: {=INDEX('T. S2 microarray results'!J:J, MATCH(TRUE, ('T. S2 microarray results'!B:B=B4) + ('T. S2 microarray results'!C:C=B4) + ('T. S2 microarray results'!D:D=B4) + ('T. S2 microarray results'!E:E=B4) + ('T. S2 microarray results'!F:F=B4) + ('T. S2 microarray results'!G:G=B4) + ('T. S2 microarray results'!H:H=B4) > 0, 0))} -> 0.5468464 | G4: {=INDEX('T. S2 microarray results'!K:K, MATCH(TRUE, ('T. S2 microarray results'!B:B=B4) + ('T. S2 microarray results'!C:C=B4) + ('T. S2 microarray results'!D:D=B4) + ('T. S2 microarray results'!E:E=B4) + ('T. S2 microarray results'!F:F=B4) + ('T. S2 microarray results'!G:G=B4) + ('T. S2 microarray results'!H:H=B4) > 0, 0))} -> 0.7314741 | H4: {=INDEX('T. S2 microarray results'!L:L, MATCH(TRUE, ('T. S2 microarray results'!B:B=B4) + ('T. S2 microarray results'!C:C=B4) + ('T. S2 microarray results'!D:D=B4) + ('T. S2 microarray results'!E:E=B4) + ('T. S2 microarray results'!F:F=B4) + ('T. S2 microarray results'!G:G=B4) + ('T. S2 microarray results'!H:H=B4) > 0, 0))} -> 0.3387958
A5: {=INDEX('T. S2 microarray results'!A:A, MATCH(TRUE, ('T. S2 microarray results'!B:B=B5) + ('T. S2 microarray results'!C:C=B5) + ('T. S2 microarray results'!D:D=B5) + ('T. S2 microarray results'!E:E=B5) + ('T. S2 microarray results'!F:F=B5) + ('T. S2 microarray results'!G:G=B5) + ('T. S2 microarray results'!H:H=B5) > 0, 0))} -> YDR264C | B5: AKR1 | C5: Candidate Gene | D5: =CONCATENATE(IF(C5="Known Longivity Gene","*",""),A5,"/",B5) -> YDR264C/AKR1 | E5: =IF(C5="Known Longivity Gene",1,0) -> 0 | F5: {=INDEX('T. S2 microarray results'!J:J, MATCH(TRUE, ('T. S2 microarray results'!B:B=B5) + ('T. S2 microarray results'!C:C=B5) + ('T. S2 microarray results'!D:D=B5) + ('T. S2 microarray results'!E:E=B5) + ('T. S2 microarray results'!F:F=B5) + ('T. S2 microarray results'!G:G=B5) + ('T. S2 microarray results'!H:H=B5) > 0, 0))} -> 0.1897815 | G5: {=INDEX('T. S2 microarray results'!K:K, MATCH(TRUE, ('T. S2 microarray results'!B:B=B5) + ('T. S2 microarray results'!C:C=B5) + ('T. S2 microarray results'!D:D=B5) + ('T. S2 microarray results'!E:E=B5) + ('T. S2 microarray results'!F:F=B5) + ('T. S2 microarray results'!G:G=B5) + ('T. S2 microarray results'!H:H=B5) > 0, 0))} -> 0.1657417 | H5: {=INDEX('T. S2 microarray results'!L:L, MATCH(TRUE, ('T. S2 microarray results'!B:B=B5) + ('T. S2 microarray results'!C:C=B5) + ('T. S2 microarray results'!D:D=B5) + ('T. S2 microarray results'!E:E=B5) + ('T. S2 microarray results'!F:F=B5) + ('T. S2 microarray results'!G:G=B5) + ('T. S2 microarray results'!H:H=B5) > 0, 0))} -> 0.1301702
A6: {=INDEX('T. S2 microarray results'!A:A, MATCH(TRUE, ('T. S2 microarray results'!B:B=B6) + ('T. S2 microarray results'!C:C=B6) + ('T. S2 microarray results'!D:D=B6) + ('T. S2 microarray results'!E:E=B6) + ('T. S2 microarray results'!F:F=B6) + ('T. S2 microarray results'!G:G=B6) + ('T. S2 microarray results'!H:H=B6) > 0, 0))} -> YNL148C | B6: ALF1 | C6: Candidate Gene | D6: =CONCATENATE(IF(C6="Known Longivity Gene","*",""),A6,"/",B6) -> YNL148C/ALF1 | E6: =IF(C6="Known Longivity Gene",1,0) -> 0 | F6: {=INDEX('T. S2 microarray results'!J:J, MATCH(TRUE, ('T. S2 microarray results'!B:B=B6) + ('T. S2 microarray results'!C:C=B6) + ('T. S2 microarray results'!D:D=B6) + ('T. S2 microarray results'!E:E=B6) + ('T. S2 microarray results'!F:F=B6) + ('T. S2 microarray results'!G:G=B6) + ('T. S2 microarray results'!H:H=B6) > 0, 0))} -> 0.3507553 | G6: {=INDEX('T. S2 microarray results'!K:K, MATCH(TRUE, ('T. S2 microarray results'!B:B=B6) + ('T. S2 microarray results'!C:C=B6) + ('T. S2 microarray results'!D:D=B6) + ('T. S2 microarray results'!E:E=B6) + ('T. S2 microarray results'!F:F=B6) + ('T. S2 microarray results'!G:G=B6) + ('T. S2 microarray results'!H:H=B6) > 0, 0))} -> 0.2453944 | H6: {=INDEX('T. S2 microarray results'!L:L, MATCH(TRUE, ('T. S2 microarray results'!B:B=B6) + ('T. S2 microarray results'!C:C=B6) + ('T. S2 microarray results'!D:D=B6) + ('T. S2 microarray results'!E:E=B6) + ('T. S2 microarray results'!F:F=B6) + ('T. S2 microarray results'!G:G=B6) + ('T. S2 microarray results'!H:H=B6) > 0, 0))} -> 0.3308809
A7: {=INDEX('T. S2 microarray results'!A:A, MATCH(TRUE, ('T. S2 microarray results'!B:B=B7) + ('T. S2 microarray results'!C:C=B7) + ('T. S2 microarray results'!D:D=B7) + ('T. S2 microarray results'!E:E=B7) + ('T. S2 microarray results'!F:F=B7) + ('T. S2 microarray results'!G:G=B7) + ('T. S2 microarray results'!H:H=B7) > 0, 0))} -> YPL120W | B7: VPS30 | C7: Candidate Gene | D7: =CONCATENATE(IF(C7="Known Longivity Gene","*",""),A7,"/",B7) -> YPL120W/VPS30 | E7: =IF(C7="Known Longivity Gene",1,0) -> 0 | F7: {=INDEX('T. S2 microarray results'!J:J, MATCH(TRUE, ('T. S2 microarray results'!B:B=B7) + ('T. S2 microarray results'!C:C=B7) + ('T. S2 microarray results'!D:D=B7) + ('T. S2 microarray results'!E:E=B7) + ('T. S2 microarray results'!F:F=B7) + ('T. S2 microarray results'!G:G=B7) + ('T. S2 microarray results'!H:H=B7) > 0, 0))} -> 0.2700111 | G7: {=INDEX('T. S2 microarray results'!K:K, MATCH(TRUE, ('T. S2 microarray results'!B:B=B7) + ('T. S2 microarray results'!C:C=B7) + ('T. S2 microarray results'!D:D=B7) + ('T. S2 microarray results'!E:E=B7) + ('T. S2 microarray results'!F:F=B7) + ('T. S2 microarray results'!G:G=B7) + ('T. S2 microarray results'!H:H=B7) > 0, 0))} -> 0.1998218 | H7: {=INDEX('T. S2 microarray results'!L:L, MATCH(TRUE, ('T. S2 microarray results'!B:B=B7) + ('T. S2 microarray results'!C:C=B7) + ('T. S2 microarray results'!D:D=B7) + ('T. S2 microarray results'!E:E=B7) + ('T. S2 microarray results'!F:F=B7) + ('T. S2 microarray results'!G:G=B7) + ('T. S2 microarray results'!H:H=B7) > 0, 0))} -> 0.3487854
A8: {=INDEX('T. S2 microarray results'!A:A, MATCH(TRUE, ('T. S2 microarray results'!B:B=B8) + ('T. S2 microarray results'!C:C=B8) + ('T. S2 microarray results'!D:D=B8) + ('T. S2 microarray results'!E:E=B8) + ('T. S2 microarray results'!F:F=B8) + ('T. S2 microarray results'!G:G=B8) + ('T. S2 microarray results'!H:H=B8) > 0, 0))} -> YLR268W | B8: SEC22 | C8: Candidate Gene | D8: =CONCATENATE(IF(C8="Known Longivity Gene","*",""),A8,"/",B8) -> YLR268W/SEC22 | E8: =IF(C8="Known Longivity Gene",1,0) -> 0 | F8: {=INDEX('T. S2 microarray results'!J:J, MATCH(TRUE, ('T. S2 microarray results'!B:B=B8) + ('T. S2 microarray results'!C:C=B8) + ('T. S2 microarray results'!D:D=B8) + ('T. S2 microarray results'!E:E=B8) + ('T. S2 microarray results'!F:F=B8) + ('T. S2 microarray results'!G:G=B8) + ('T. S2 microarray results'!H:H=B8) > 0, 0))} -> 0.5011193 | G8: {=INDEX('T. S2 microarray results'!K:K, MATCH(TRUE, ('T. S2 microarray results'!B:B=B8) + ('T. S2 microarray results'!C:C=B8) + ('T. S2 microarray results'!D:D=B8) + ('T. S2 microarray results'!E:E=B8) + ('T. S2 microarray results'!F:F=B8) + ('T. S2 microarray results'!G:G=B8) + ('T. S2 microarray results'!H:H=B8) > 0, 0))} -> 0.6050925 | H8: {=INDEX('T. S2 microarray results'!L:L, MATCH(TRUE, ('T. S2 microarray results'!B:B=B8) + ('T. S2 microarray results'!C:C=B8) + ('T. S2 microarray results'!D:D=B8) + ('T. S2 microarray results'!E:E=B8) + ('T. S2 microarray results'!F:F=B8) + ('T. S2 microarray results'!G:G=B8) + ('T. S2 microarray results'!H:H=B8) > 0, 0))} -> 0.5622788
A9: {=INDEX('T. S2 microarray results'!A:A, MATCH(TRUE, ('T. S2 microarray results'!B:B=B9) + ('T. S2 microarray results'!C:C=B9) + ('T. S2 microarray results'!D:D=B9) + ('T. S2 microarray results'!E:E=B9) + ('T. S2 microarray results'!F:F=B9) + ('T. S2 microarray results'!G:G=B9) + ('T. S2 microarray results'!H:H=B9) > 0, 0))} -> YKL015W | B9: PUT3 | C9: Candidate Gene | D9: =CONCATENATE(IF(C9="Known Longivity Gene","*",""),A9,"/",B9) -> YKL015W/PUT3 | E9: =IF(C9="Known Longivity Gene",1,0) -> 0 | F9: {=INDEX('T. S2 microarray results'!J:J, MATCH(TRUE, ('T. S2 microarray results'!B:B=B9) + ('T. S2 microarray results'!C:C=B9) + ('T. S2 microarray results'!D:D=B9) + ('T. S2 microarray results'!E:E=B9) + ('T. S2 microarray results'!F:F=B9) + ('T. S2 microarray results'!G:G=B9) + ('T. S2 microarray results'!H:H=B9) > 0, 0))} -> 0.0173433 | G9: {=INDEX('T. S2 microarray results'!K:K, MATCH(TRUE, ('T. S2 microarray results'!B:B=B9) + ('T. S2 microarray results'!C:C=B9) + ('T. S2 microarray results'!D:D=B9) + ('T. S2 microarray results'!E:E=B9) + ('T. S2 microarray results'!F:F=B9) + ('T. S2 microarray results'!G:G=B9) + ('T. S2 microarray results'!H:H=B9) > 0, 0))} -> -0.6754868 | H9: {=INDEX('T. S2 microarray results'!L:L, MATCH(TRUE, ('T. S2 microarray results'!B:B=B9) + ('T. S2 microarray results'!C:C=B9) + ('T. S2 microarray results'!D:D=B9) + ('T. S2 microarray results'!E:E=B9) + ('T. S2 microarray results'!F:F=B9) + ('T. S2 microarray results'!G:G=B9) + ('T. S2 microarray results'!H:H=B9) > 0, 0))} -> -0.7210857
A10: {=INDEX('T. S2 microarray results'!A:A, MATCH(TRUE, ('T. S2 microarray results'!B:B=B10) + ('T. S2 microarray results'!C:C=B10) + ('T. S2 microarray results'!D:D=B10) + ('T. S2 microarray results'!E:E=B10) + ('T. S2 microarray results'!F:F=B10) + ('T. S2 microarray results'!G:G=B10) + ('T. S2 microarray results'!H:H=B10) > 0, 0))} -> YCL037C | B10: SRO9 | C10: Candidate Gene | D10: =CONCATENATE(IF(C10="Known Longivity Gene","*",""),A10,"/",B10) -> YCL037C/SRO9 | E10: =IF(C10="Known Longivity Gene",1,0) -> 0 | F10: {=INDEX('T. S2 microarray results'!J:J, MATCH(TRUE, ('T. S2 microarray results'!B:B=B10) + ('T. S2 microarray results'!C:C=B10) + ('T. S2 microarray results'!D:D=B10) + ('T. S2 microarray results'!E:E=B10) + ('T. S2 microarray results'!F:F=B10) + ('T. S2 microarray results'!G:G=B10) + ('T. S2 microarray results'!H:H=B10) > 0, 0))} -> 0.01512819 | G10: {=INDEX('T. S2 microarray results'!K:K, MATCH(TRUE, ('T. S2 microarray results'!B:B=B10) + ('T. S2 microarray results'!C:C=B10) + ('T. S2 microarray results'!D:D=B10) + ('T. S2 microarray results'!E:E=B10) + ('T. S2 microarray results'!F:F=B10) + ('T. S2 microarray results'!G:G=B10) + ('T. S2 microarray results'!H:H=B10) > 0, 0))} -> 0.9660928 | H10: {=INDEX('T. S2 microarray results'!L:L, MATCH(TRUE, ('T. S2 microarray results'!B:B=B10) + ('T. S2 microarray results'!C:C=B10) + ('T. S2 microarray results'!D:D=B10) + ('T. S2 microarray results'!E:E=B10) + ('T. S2 microarray results'!F:F=B10) + ('T. S2 microarray results'!G:G=B10) + ('T. S2 microarray results'!H:H=B10) > 0, 0))} -> 0.07661917
A11: {=INDEX('T. S2 microarray results'!A:A, MATCH(TRUE, ('T. S2 microarray results'!B:B=B11) + ('T. S2 microarray results'!C:C=B11) + ('T. S2 microarray results'!D:D=B11) + ('T. S2 microarray results'!E:E=B11) + ('T. S2 microarray results'!F:F=B11) + ('T. S2 microarray results'!G:G=B11) + ('T. S2 microarray results'!H:H=B11) > 0, 0))} -> YKR026C | B11: GCN3 | C11: Candidate Gene | D11: =CONCATENATE(IF(C11="Known Longivity Gene","*",""),A11,"/",B11) -> YKR026C/GCN3 | E11: =IF(C11="Known Longivity Gene",1,0) -> 0 | F11: {=INDEX('T. S2 microarray results'!J:J, MATCH(TRUE, ('T. S2 microarray results'!B:B=B11) + ('T. S2 microarray results'!C:C=B11) + ('T. S2 microarray results'!D:D=B11) + ('T. S2 microarray results'!E:E=B11) + ('T. S2 microarray results'!F:F=B11) + ('T. S2 microarray results'!G:G=B11) + ('T. S2 microarray results'!H:H=B11) > 0, 0))} -> 0.09773856 | G11: {=INDEX('T. S2 microarray results'!K:K, MATCH(TRUE, ('T. S2 microarray results'!B:B=B11) + ('T. S2 microarray results'!C:C=B11) + ('T. S2 microarray results'!D:D=B11) + ('T. S2 microarray results'!E:E=B11) + ('T. S2 microarray results'!F:F=B11) + ('T. S2 microarray results'!G:G=B11) + ('T. S2 microarray results'!H:H=B11) > 0, 0))} -> 0.5938986 | H11: {=INDEX('T. S2 microarray results'!L:L, MATCH(TRUE, ('T. S2 microarray results'!B:B=B11) + ('T. S2 microarray results'!C:C=B11) + ('T. S2 microarray results'!D:D=B11) + ('T. S2 microarray results'!E:E=B11) + ('T. S2 microarray results'!F:F=B11) + ('T. S2 microarray results'!G:G=B11) + ('T. S2 microarray results'!H:H=B11) > 0, 0))} -> 0.0981128
A12: {=INDEX('T. S2 microarray results'!A:A, MATCH(TRUE, ('T. S2 microarray results'!B:B=B12) + ('T. S2 microarray results'!C:C=B12) + ('T. S2 microarray results'!D:D=B12) + ('T. S2 microarray results'!E:E=B12) + ('T. S2 microarray results'!F:F=B12) + ('T. S2 microarray results'!G:G=B12) + ('T. S2 microarray results'!H:H=B12) > 0, 0))} -> YKL017C | B12: HCS1 | C12: Candidate Gene | D12: =CONCATENATE(IF(C12="Known Longivity Gene","*",""),A12,"/",B12) -> YKL017C/HCS1 | E12: =IF(C12="Known Longivity Gene",1,0) -> 0 | F12: {=INDEX('T. S2 microarray results'!J:J, MATCH(TRUE, ('T. S2 microarray results'!B:B=B12) + ('T. S2 microarray results'!C:C=B12) + ('T. S2 microarray results'!D:D=B12) + ('T. S2 microarray results'!E:E=B12) + ('T. S2 microarray results'!F:F=B12) + ('T. S2 microarray results'!G:G=B12) + ('T. S2 microarray results'!H:H=B12) > 0, 0))} -> 0.1866696 | G12: {=INDEX('T. S2 microarray results'!K:K, MATCH(TRUE, ('T. S2 microarray results'!B:B=B12) + ('T. S2 microarray results'!C:C=B12) + ('T. S2 microarray results'!D:D=B12) + ('T. S2 microarray results'!E:E=B12) + ('T. S2 microarray results'!F:F=B12) + ('T. S2 microarray results'!G:G=B12) + ('T. S2 microarray results'!H:H=B12) > 0, 0))} -> -0.3403223 | H12: {=INDEX('T. S2 microarray results'!L:L, MATCH(TRUE, ('T. S2 microarray results'!B:B=B12) + ('T. S2 microarray results'!C:C=B12) + ('T. S2 microarray results'!D:D=B12) + ('T. S2 microarray results'!E:E=B12) + ('T. S2 microarray results'!F:F=B12) + ('T. S2 microarray results'!G:G=B12) + ('T. S2 microarray results'!H:H=B12) > 0, 0))} -> 0.005202552
A13: {=INDEX('T. S2 microarray results'!A:A, MATCH(TRUE, ('T. S2 microarray results'!B:B=B13) + ('T. S2 microarray results'!C:C=B13) + ('T. S2 microarray results'!D:D=B13) + ('T. S2 microarray results'!E:E=B13) + ('T. S2 microarray results'!F:F=B13) + ('T. S2 microarray results'!G:G=B13) + ('T. S2 microarray results'!H:H=B13) > 0, 0))} -> YCR002C | B13: CDC10 | C13: Candidate Gene | D13: =CONCATENATE(IF(C13="Known Longivity Gene","*",""),A13,"/",B13) -> YCR002C/CDC10 | E13: =IF(C13="Known Longivity Gene",1,0) -> 0 | F13: {=INDEX('T. S2 microarray results'!J:J, MATCH(TRUE, ('T. S2 microarray results'!B:B=B13) + ('T. S2 microarray results'!C:C=B13) + ('T. S2 microarray results'!D:D=B13) + ('T. S2 microarray results'!E:E=B13) + ('T. S2 microarray results'!F:F=B13) + ('T. S2 microarray results'!G:G=B13) + ('T. S2 microarray results'!H:H=B13) > 0, 0))} -> -0.2811855 | G13: {=INDEX('T. S2 microarray results'!K:K, MATCH(TRUE, ('T. S2 microarray results'!B:B=B13) + ('T. S2 microarray results'!C:C=B13) + ('T. S2 microarray results'!D:D=B13) + ('T. S2 microarray results'!E:E=B13) + ('T. S2 microarray results'!F:F=B13) + ('T. S2 microarray results'!G:G=B13) + ('T. S2 microarray results'!H:H=B13) > 0, 0))} -> -0.4761917 | H13: {=INDEX('T. S2 microarray results'!L:L, MATCH(TRUE, ('T. S2 microarray results'!B:B=B13) + ('T. S2 microarray results'!C:C=B13) + ('T. S2 microarray results'!D:D=B13) + ('T. S2 microarray results'!E:E=B13) + ('T. S2 microarray results'!F:F=B13) + ('T. S2 microarray results'!G:G=B13) + ('T. S2 microarray results'!H:H=B13) > 0, 0))} -> -0.03376408
... A171: {=INDEX('T. S2 microarray results'!A:A, MATCH(TRUE, ('T. S2 microarray results'!B:B=B171) + ('T. S2 microarray results'!C:C=B171) + ('T. S2 microarray results'!D:D=B171) + ('T. S2 microarray results'!E:E=B171) + ('T. S2 microarray results'!F:F=B171) + ('T. S2 microarray results'!G:G=B171) + ('T. S2 microarray results'!H:H=B171) > 0, 0))} -> YMR273C | B171: ZDS1 | C171: Known Longivity Gene | D171: =CONCATENATE(IF(C171="Known Longivity Gene","*",""),A171,"/",B171) -> *YMR273C/ZDS1 | E171: =IF(C171="Known Longivity Gene",1,0) -> 1 | F171: {=INDEX('T. S2 microarray results'!J:J, MATCH(TRUE, ('T. S2 microarray results'!B:B=B171) + ('T. S2 microarray results'!C:C=B171) + ('T. S2 microarray results'!D:D=B171) + ('T. S2 microarray results'!E:E=B171) + ('T. S2 microarray results'!F:F=B171) + ('T. S2 microarray results'!G:G=B171) + ('T. S2 microarray results'!H:H=B171) > 0, 0))} -> -0.5049685 | G171: {=INDEX('T. S2 microarray results'!K:K, MATCH(TRUE, ('T. S2 microarray results'!B:B=B171) + ('T. S2 microarray results'!C:C=B171) + ('T. S2 microarray results'!D:D=B171) + ('T. S2 microarray results'!E:E=B171) + ('T. S2 microarray results'!F:F=B171) + ('T. S2 microarray results'!G:G=B171) + ('T. S2 microarray results'!H:H=B171) > 0, 0))} -> -0.9081731 | H171: {=INDEX('T. S2 microarray results'!L:L, MATCH(TRUE, ('T. S2 microarray results'!B:B=B171) + ('T. S2 microarray results'!C:C=B171) + ('T. S2 microarray results'!D:D=B171) + ('T. S2 microarray results'!E:E=B171) + ('T. S2 microarray results'!F:F=B171) + ('T. S2 microarray results'!G:G=B171) + ('T. S2 microarray results'!H:H=B171) > 0, 0))} -> -0.4852084
